emailsms.py: process with pid 11920 started.
/home/pi/iot_home_security/lib/applications/email_configuration/emailsms.py:2: unknown encoding name: latin-1 (ArgumentError)
	from /home/pi/.rvm/gems/ruby-2.3.0/gems/daemons-1.2.4/lib/daemons/application.rb:219:in `load'
	from /home/pi/.rvm/gems/ruby-2.3.0/gems/daemons-1.2.4/lib/daemons/application.rb:219:in `start_load'
	from /home/pi/.rvm/gems/ruby-2.3.0/gems/daemons-1.2.4/lib/daemons/application.rb:298:in `start'
	from /home/pi/.rvm/gems/ruby-2.3.0/gems/daemons-1.2.4/lib/daemons/controller.rb:56:in `run'
	from /home/pi/.rvm/gems/ruby-2.3.0/gems/daemons-1.2.4/lib/daemons.rb:148:in `block in run'
	from /home/pi/.rvm/gems/ruby-2.3.0/gems/daemons-1.2.4/lib/daemons/cmdline.rb:92:in `catch_exceptions'
	from /home/pi/.rvm/gems/ruby-2.3.0/gems/daemons-1.2.4/lib/daemons.rb:147:in `run'
	from ./email_control.rb:14:in `<main>'
